<?xml version="1.0" ?>
<robot name="sciurus17">
  <link name="base_link">
    <visual>
      <geometry>
        <mesh filename="package://sciurus17_description/meshes/visual/Base.stl" scale="1.0 1.0 1.0"/>
      </geometry>
      <material name="white_color">
        <color rgba="0.9 0.9 0.9 1"/>
      </material>
    </visual>
    <collision>
      <origin rpy="0 0 0" xyz="0.0 0.0 0.0"/>
      <geometry>
        <mesh filename="package://sciurus17_description/meshes/collision/Base.stl" scale="1.0 1.0 1.0"/>
      </geometry>
    </collision>
    <inertial>
      <origin rpy="0 0 0" xyz="-0.00669 0.000049 0.017868"/>
      <inertia ixx="1.0" ixy="0.0" ixz="0.0" iyx="0.0" iyy="1.0" iyz="0.0" izx="0.0" izy="0.0" izz="1.0"/>
      <mass value="0.387313"/>
    </inertial>
  </link>
  <link name="body_link">
    <visual>
      <geometry>
        <mesh filename="package://sciurus17_description/meshes/visual/Body.stl" scale="1.0 1.0 1.0"/>
      </geometry>
      <material name="white_color">
        <color rgba="0.9 0.9 0.9 1"/>
      </material>
    </visual>
    <collision>
      <origin rpy="0 0 0" xyz="0.0 0.0 0.0"/>
      <geometry>
        <mesh filename="package://sciurus17_description/meshes/collision/Body.stl" scale="1.0 1.0 1.0"/>
      </geometry>
    </collision>
    <inertial>
      <origin rpy="0 0 0" xyz="-0.00669 0.000049 0.017868"/>
      <inertia ixx="1.0" ixy="0.0" ixz="0.0" iyx="0.0" iyy="1.0" iyz="0.0" izx="0.0" izy="0.0" izz="1.0"/>
      <mass value="0.387313"/>
    </inertial>
  </link>

  <link name="neck_pitch_link">
    <visual>
      <origin rpy="1.5708 0 0" xyz="0.0 0.0 0.0"/>
      <geometry>
        <mesh filename="package://sciurus17_description/meshes/visual/Neck2.stl" scale="1.0 1.0 1.0"/>
      </geometry>
      <material name="white_color"/>
    </visual>
    <collision>
      <origin rpy="1.5708 0 0" xyz="0.0 0.0 0.0"/>
      <geometry>
        <mesh filename="package://sciurus17_description/meshes/collision/Neck2.stl" scale="1.0 1.0 1.0"/>
      </geometry>
    </collision>
    <inertial>
      <origin rpy="0 0 0" xyz="0.000013 -0.000407 0.046345"/>
      <inertia ixx="1.0" ixy="0.0" ixz="0.0" iyx="0.0" iyy="1.0" iyz="0.0" izx="0.0" izy="0.0" izz="1.0"/>
      <mass value="0.235377"/>
    </inertial>
  </link>
  <link name="neck_yaw_link">
    <visual>
      <geometry>
        <mesh filename="package://sciurus17_description/meshes/visual/Neck1.stl" scale="1.0 1.0 1.0"/>
      </geometry>
      <material name="white_color"/>
    </visual>
    <collision>
      <geometry>
        <mesh filename="package://sciurus17_description/meshes/collision/Neck1.stl" scale="1.0 1.0 1.0"/>
      </geometry>
    </collision>
    <inertial>
      <inertia ixx="1.0" ixy="0.0" ixz="0.0" iyx="0.0" iyy="1.0" iyz="0.0" izx="0.0" izy="0.0" izz="1.0"/>
      <mass value="0.120005"/>
    </inertial>
  </link>
  <link name="camera_link">
    <visual>
      <origin xyz="0 0 0" rpy="0 0 0"/>
      <geometry>
        <cylinder length="0.002" radius="0.003"/>
      </geometry>
      <material name="white_color"/>
    </visual>
    <collision>
      <origin xyz="0.0 0.0 0.0" rpy="0 0 0"/>
      <geometry>
        <cylinder length="0.002" radius="0.003"/>
      </geometry>
    </collision>
    <inertial>
      <mass value="0.1" />
      <origin xyz="0 0 0" />
      <inertia ixx="0.003881243" ixy="0.0" ixz="0.0" iyy="0.000498940" iyz="0.0" izz="0.003879257" />
    </inertial>
  </link>
  <link name="chest_camera_link">
    <visual>
      <origin xyz="0 0 0" rpy="0 0 0"/>
      <geometry>
        <cylinder length="0.002" radius="0.003"/>
      </geometry>
      <material name="white_color"/>
    </visual>
    <collision>
      <origin xyz="0.0 0.0 0.0" rpy="0 0 0"/>
      <geometry>
        <cylinder length="0.002" radius="0.003"/>
      </geometry>
    </collision>
    <inertial>
      <mass value="0.1" />
      <origin xyz="0 0 0" />
      <inertia ixx="0.003881243" ixy="0.0" ixz="0.0" iyy="0.000498940" iyz="0.0" izz="0.003879257" />
    </inertial>
  </link>

  <link name="r_link1">
    <visual>
      <origin rpy="1.5708 0 0" xyz="0.0 0.0 0.0"/>
      <geometry>
        <mesh filename="package://sciurus17_description/meshes/visual/R_Link1.stl" scale="1.0 1.0 1.0"/>
      </geometry>
      <material name="white_color"/>
    </visual>
    <collision>
      <origin rpy="1.5708 0 0" xyz="0.0 0.0 0.0"/>
      <geometry>
        <mesh filename="package://sciurus17_description/meshes/collision/R_Link1.stl" scale="1.0 1.0 1.0"/>
      </geometry>
    </collision>
    <inertial>
      <origin rpy="1.5708 0 0" xyz="-0.011533 0.000021 0.083707"/>
      <inertia ixx="1.0" ixy="0.0" ixz="0.0" iyx="0.0" iyy="1.0" iyz="0.0" izx="0.0" izy="0.0" izz="1.0"/>
      <mass value="0.340878"/>
    </inertial>
  </link>
  <link name="r_link2">
    <visual>
      <origin rpy="0 1.5708 0" xyz="0.0 0.0 0.0"/>
      <geometry>
        <mesh filename="package://sciurus17_description/meshes/visual/R_Link2.stl" scale="-1.0 1.0 1.0"/>
      </geometry>
      <material name="white_color"/>
    </visual>
    <collision>
      <origin rpy="0 1.5708 0" xyz="0.0 0.0 0.0"/>
      <geometry>
        <mesh filename="package://sciurus17_description/meshes/collision/R_Link2.stl" scale="-1.0 1.0 1.0"/>
      </geometry>
    </collision>
    <inertial>
      <origin rpy="0 1.5708 0" xyz="-0.008641 0.083071 -0.000086"/>
      <inertia ixx="1.0" ixy="0.0" ixz="0.0" iyx="0.0" iyy="1.0" iyz="0.0" izx="0.0" izy="0.0" izz="1.0"/>
      <mass value="0.230634"/>
    </inertial>
  </link>
  <link name="r_link3">
    <visual>
      <origin rpy="1.5708 0 0" xyz="0.0 0.0 0.0"/>
      <geometry>
        <mesh filename="package://sciurus17_description/meshes/visual/L_Link3.stl" scale="1.0 -1.0 1.0"/>
      </geometry>
      <material name="white_color"/>
    </visual>
    <collision>
      <origin rpy="1.5708 0 0" xyz="0.0 0.0 0.0"/>
      <geometry>
        <mesh filename="package://sciurus17_description/meshes/collision/L_Link3.stl" scale="1.0 -1.0 1.0"/>
      </geometry>
    </collision>
    <inertial>
      <origin rpy="1.5708 0 0" xyz="0.0 0.0 0.0"/>
      <inertia ixx="1.0" ixy="0.0" ixz="0.0" iyx="0.0" iyy="1.0" iyz="0.0" izx="0.0" izy="0.0" izz="1.0"/>
      <mass value="0.192709"/>
    </inertial>
  </link>
  <link name="r_link4">
    <visual>
      <origin rpy="0 0 0" xyz="0.0 0.0 0.0"/>
      <geometry>
        <mesh filename="package://sciurus17_description/meshes/visual/R_Link4.stl" scale="1.0 1.0 1.0"/>
      </geometry>
      <material name="white_color"/>
    </visual>
    <collision>
      <origin rpy="0 0 0" xyz="0.0 0.0 0.0"/>
      <geometry>
        <mesh filename="package://sciurus17_description/meshes/collision/R_Link4.stl" scale="1.0 1.0 1.0"/>
      </geometry>
    </collision>
    <inertial>
      <origin rpy="0 0 0" xyz="0.005713 -0.003707 0.000781"/>
      <inertia ixx="1.0" ixy="0.0" ixz="0.0" iyx="0.0" iyy="1.0" iyz="0.0" izx="0.0" izy="0.0" izz="1.0"/>
      <mass value="0.130549"/>
    </inertial>
  </link>
  <link name="r_link5">
    <visual>
      <origin rpy="1.5708 0 0" xyz="0.0 0.0 0.0"/>
      <geometry>
        <mesh filename="package://sciurus17_description/meshes/visual/R_Link5.stl" scale="1.0 1.0 1.0"/>
      </geometry>
      <material name="white_color"/>
    </visual>
    <visual>
      <origin xyz="0.032 -0.074 0.0345" rpy="0 0 -2.0944"/>
      <geometry>
        <mesh filename="package://sciurus17_description/meshes/visual/Logo_Rabbit.stl" scale="1.0 1.0 1.0"/>
      </geometry>
      <material name="red_color">
        <color rgba="0.8984375 0.0 0.0703125 1"/>
      </material>
    </visual>
    <visual>
      <origin xyz="0.013 -0.107 0.0345" rpy="0 0 -2.0944"/>
      <geometry>
        <mesh filename="package://sciurus17_description/meshes/visual/Logo_Corp.stl" scale="1.0 1.0 1.0"/>
      </geometry>
      <material name="black_color">
        <color rgba="0.2 0.2 0.2 1"/>
      </material>
    </visual>
    <collision>
      <origin rpy="1.5708 0 0" xyz="0.0 0.0 0.0"/>
      <geometry>
        <mesh filename="package://sciurus17_description/meshes/collision/R_Link5.stl" scale="1.0 1.0 1.0"/>
      </geometry>
    </collision>
    <inertial>
      <origin rpy="1.5708 0 0" xyz="0.000425 -0.000896 0.018691"/>
      <inertia ixx="1.0" ixy="0.0" ixz="0.0" iyx="0.0" iyy="1.0" iyz="0.0" izx="0.0" izy="0.0" izz="1.0"/>
      <mass value="0.119807"/>
    </inertial>
  </link>
  <link name="r_link5_armarker">
    <visual>
      <origin rpy="0 0 0" xyz="0.0 0.0 0.0"/>
      <geometry>
        <cylinder length="0.001" radius="0.001"/>
      </geometry>
      <material name="white_color"/>
    </visual>
  </link>
  <link name="r_link6">
    <visual>
      <origin rpy="0 0 0" xyz="0.0 0.0 0.0"/>
      <geometry>
        <mesh filename="package://sciurus17_description/meshes/visual/R_Link6.stl" scale="1.0 1.0 1.0"/>
      </geometry>
      <material name="white_color"/>
    </visual>
    <collision>
      <origin rpy="0 0 0" xyz="0.0 0.0 0.0"/>
      <geometry>
        <mesh filename="package://sciurus17_description/meshes/collision/L_Link6.stl" scale="1.0 1.0 1.0"/>
      </geometry>
    </collision>
    <inertial>
      <origin rpy="0 0 0" xyz="0.000425 -0.000896 0.018691"/>
      <inertia ixx="1.0" ixy="0.0" ixz="0.0" iyx="0.0" iyy="1.0" iyz="0.0" izx="0.0" izy="0.0" izz="1.0"/>
      <mass value="0.119807"/>
    </inertial>
  </link>
  <link name="r_link7">
    <visual>
      <origin rpy="1.5708 0 0" xyz="0.0 0.0 0.0"/>
      <geometry>
        <mesh filename="package://sciurus17_description/meshes/visual/R_Link7.stl" scale="1.0 1.0 1.0"/>
      </geometry>
      <material name="red_color">
        <color rgba="0.8984375 0.0 0.0703125 1"/>
      </material>
    </visual>
    <collision>
      <origin rpy="1.5708 0 0" xyz="0.0 0.0 0.0"/>
      <geometry>
        <mesh filename="package://sciurus17_description/meshes/collision/R_Link7.stl" scale="1.0 1.0 1.0"/>
      </geometry>
    </collision>
    <inertial>
      <origin rpy="1.5708 0 0" xyz="0.000425 -0.000896 0.018691"/>
      <inertia ixx="1.0" ixy="0.0" ixz="0.0" iyx="0.0" iyy="1.0" iyz="0.0" izx="0.0" izy="0.0" izz="1.0"/>
      <mass value="0.119807"/>
    </inertial>
  </link>
  <link name="r_handA_link">
    <visual>
      <!--origin rpy="3.14159 0 0" xyz="0.0 0.0 0.0"/-->
      <origin rpy="0 0 0" xyz="0.0 0.0 0.0"/>
      <geometry>
        <mesh filename="package://sciurus17_description/meshes/visual/R_HandA.stl" scale="1.0 1.0 1.0"/>
      </geometry>
      <material name="red_color">
        <color rgba="0.8984375 0.0 0.0703125 1"/>
      </material>
    </visual>
    <collision>
      <origin rpy="0 0 0" xyz="0.0 0.0 0.0"/>
      <geometry>
        <mesh filename="package://sciurus17_description/meshes/collision/R_HandA.stl" scale="1.0 1.0 1.0"/>
      </geometry>
    </collision>
    <inertial>
      <origin rpy="0 0 0" xyz="0.000425 -0.000896 0.018691"/>
      <inertia ixx="1.0" ixy="0.0" ixz="0.0" iyx="0.0" iyy="1.0" iyz="0.0" izx="0.0" izy="0.0" izz="1.0"/>
      <mass value="0.119807"/>
    </inertial>
  </link>
  <link name="r_handB_link">
    <visual>
      <!-- origin rpy="3.14159 0 0" xyz="0.0 0.0 0.0"/ -->
      <origin rpy="0 0 0" xyz="0.0 0.0 0.0"/>
      <geometry>
        <mesh filename="package://sciurus17_description/meshes/visual/R_HandB.stl" scale="1.0 1.0 1.0"/>
      </geometry>
      <material name="red_color">
        <color rgba="0.8984375 0.0 0.0703125 1"/>
      </material>
    </visual>
    <collision>
      <origin rpy="0 0 0" xyz="0.0 0.0 0.0"/>
      <geometry>
        <mesh filename="package://sciurus17_description/meshes/collision/R_HandB.stl" scale="1.0 1.0 1.0"/>
      </geometry>
    </collision>
    <inertial>
      <origin rpy="0 0 0" xyz="0.000425 -0.000896 0.018691"/>
      <inertia ixx="1.0" ixy="0.0" ixz="0.0" iyx="0.0" iyy="1.0" iyz="0.0" izx="0.0" izy="0.0" izz="1.0"/>
      <mass value="0.119807"/>
    </inertial>
  </link>

  <link name="l_link1">
    <visual>
      <origin rpy="-1.5708 0 0" xyz="0.0 0.0 0.0"/>
      <geometry>
        <mesh filename="package://sciurus17_description/meshes/visual/L_Link1.stl" scale="1.0 1.0 1.0"/>
      </geometry>
      <material name="white_color"/>
    </visual>
    <collision>
      <origin rpy="-1.5708 0 0" xyz="0.0 0.0 0.0"/>
      <geometry>
        <mesh filename="package://sciurus17_description/meshes/collision/L_Link1.stl" scale="1.0 1.0 1.0"/>
      </geometry>
    </collision>
    <inertial>
      <origin rpy="-1.5708 0 0" xyz="-0.011533 0.000021 0.083707"/>
      <inertia ixx="1.0" ixy="0.0" ixz="0.0" iyx="0.0" iyy="1.0" iyz="0.0" izx="0.0" izy="0.0" izz="1.0"/>
      <mass value="0.340878"/>
    </inertial>
  </link>
  <link name="l_link2">
    <visual>
      <origin rpy="0 -1.5708 0" xyz="0.0 0.0 0.0"/>
      <geometry>
        <mesh filename="package://sciurus17_description/meshes/visual/L_Link2.stl" scale="1.0 1.0 -1.0"/>
      </geometry>
      <material name="white_color"/>
    </visual>
    <collision>
      <origin rpy="0 -1.5708 0" xyz="0.0 0.0 0.0"/>
      <geometry>
        <mesh filename="package://sciurus17_description/meshes/collision/L_Link2.stl" scale="1.0 1.0 -1.0"/>
      </geometry>
    </collision>
    <inertial>
      <origin rpy="0 -1.5708 0" xyz="-0.008641 0.083071 -0.000086"/>
      <inertia ixx="1.0" ixy="0.0" ixz="0.0" iyx="0.0" iyy="1.0" iyz="0.0" izx="0.0" izy="0.0" izz="1.0"/>
      <mass value="0.230634"/>
    </inertial>
  </link>
  <link name="l_link3">
    <visual>
      <origin rpy="-1.5708 0 0" xyz="0.0 0.0 0.0"/>
      <geometry>
        <mesh filename="package://sciurus17_description/meshes/visual/L_Link3.stl" scale="1.0 1.0 1.0"/>
      </geometry>
      <material name="white_color"/>
    </visual>
    <collision>
      <origin rpy="-1.5708 0 0" xyz="0.0 0.0 0.0"/>
      <geometry>
        <mesh filename="package://sciurus17_description/meshes/collision/L_Link3.stl" scale="1.0 1.0 1.0"/>
      </geometry>
    </collision>
    <inertial>
      <origin rpy="-1.5708 0 0" xyz="0.0 0.0 0.0"/>
      <inertia ixx="1.0" ixy="0.0" ixz="0.0" iyx="0.0" iyy="1.0" iyz="0.0" izx="0.0" izy="0.0" izz="1.0"/>
      <mass value="0.192709"/>
    </inertial>
  </link>
  <link name="l_link4">
    <visual>
      <origin rpy="0 0 0" xyz="0.0 0.0 0.0"/>
      <geometry>
        <mesh filename="package://sciurus17_description/meshes/visual/L_Link4.stl" scale="1.0 1.0 1.0"/>
      </geometry>
      <material name="white_color"/>
    </visual>
    <collision>
      <origin rpy="0 0 0" xyz="0.0 0.0 0.0"/>
      <geometry>
        <mesh filename="package://sciurus17_description/meshes/collision/L_Link4.stl" scale="1.0 1.0 1.0"/>
      </geometry>
    </collision>
    <inertial>
      <origin rpy="0 0 0" xyz="0.005713 -0.003707 0.000781"/>
      <inertia ixx="1.0" ixy="0.0" ixz="0.0" iyx="0.0" iyy="1.0" iyz="0.0" izx="0.0" izy="0.0" izz="1.0"/>
      <mass value="0.130549"/>
    </inertial>
  </link>
  <link name="l_link5">
    <visual>
      <origin rpy="-1.5708 0 0" xyz="0.0 0.0 0.0"/>
      <geometry>
        <mesh filename="package://sciurus17_description/meshes/visual/L_Link5.stl" scale="1.0 1.0 1.0"/>
      </geometry>
      <material name="white_color"/>
    </visual>
    <visual>
      <origin xyz="0.032 0.074 -0.0346" rpy="3.1415926 0 2.0944"/>
      <geometry>
        <mesh filename="package://sciurus17_description/meshes/visual/Logo_Rabbit.stl" scale="1.0 1.0 1.0"/>
      </geometry>
      <material name="red_color">
        <color rgba="0.8984375 0.0 0.0703125 1"/>
      </material>
    </visual>
    <visual>
      <origin xyz="0.013 0.107 -0.0346" rpy="3.1415926 0 2.0944"/>
      <geometry>
        <mesh filename="package://sciurus17_description/meshes/visual/Logo_Corp.stl" scale="1.0 1.0 1.0"/>
      </geometry>
      <material name="black_color">
        <color rgba="0.2 0.2 0.2 1"/>
      </material>
    </visual>
    <collision>
      <origin rpy="-1.5708 0 0" xyz="0.0 0.0 0.0"/>
      <geometry>
        <mesh filename="package://sciurus17_description/meshes/collision/L_Link5.stl" scale="1.0 1.0 1.0"/>
      </geometry>
    </collision>
    <inertial>
      <origin rpy="-1.5708 0 0" xyz="0.000425 -0.000896 0.018691"/>
      <inertia ixx="1.0" ixy="0.0" ixz="0.0" iyx="0.0" iyy="1.0" iyz="0.0" izx="0.0" izy="0.0" izz="1.0"/>
      <mass value="0.119807"/>
    </inertial>
  </link>
  <link name="l_link5_armarker">
    <visual>
      <origin rpy="0 0 0" xyz="0.0 0.0 0.0"/>
      <geometry>
        <cylinder length="0.001" radius="0.001"/>
      </geometry>
      <material name="white_color"/>
    </visual>
  </link>
  <link name="l_link6">
    <visual>
      <origin rpy="0 0 0" xyz="0.0 0.0 0.0"/>
      <geometry>
        <mesh filename="package://sciurus17_description/meshes/visual/L_Link6.stl" scale="1.0 1.0 1.0"/>
      </geometry>
      <material name="white_color"/>
    </visual>
    <collision>
      <origin rpy="0 0 0" xyz="0.0 0.0 0.0"/>
      <geometry>
        <mesh filename="package://sciurus17_description/meshes/collision/L_Link6.stl" scale="1.0 1.0 1.0"/>
      </geometry>
    </collision>
    <inertial>
      <origin rpy="0 0 0" xyz="0.000425 -0.000896 0.018691"/>
      <inertia ixx="1.0" ixy="0.0" ixz="0.0" iyx="0.0" iyy="1.0" iyz="0.0" izx="0.0" izy="0.0" izz="1.0"/>
      <mass value="0.119807"/>
    </inertial>
  </link>
  <link name="l_link7">
    <visual>
      <origin rpy="1.5708 0 0" xyz="0.0 0.0 0.0"/>
      <geometry>
        <mesh filename="package://sciurus17_description/meshes/visual/L_Link7.stl" scale="1.0 1.0 1.0"/>
      </geometry>
      <material name="red_color">
        <color rgba="0.8984375 0.0 0.0703125 1"/>
      </material>
    </visual>
    <collision>
      <origin rpy="1.5708 0 0" xyz="0.0 0.0 0.0"/>
      <geometry>
        <mesh filename="package://sciurus17_description/meshes/collision/L_Link7.stl" scale="1.0 1.0 1.0"/>
      </geometry>
    </collision>
    <inertial>
      <origin rpy="1.5708 0 0" xyz="0.000425 -0.000896 0.018691"/>
      <inertia ixx="1.0" ixy="0.0" ixz="0.0" iyx="0.0" iyy="1.0" iyz="0.0" izx="0.0" izy="0.0" izz="1.0"/>
      <mass value="0.119807"/>
    </inertial>
  </link>
  <link name="l_handA_link">
    <visual>
      <origin rpy="0 0 0" xyz="0.0 0.0 0.0"/>
      <geometry>
        <mesh filename="package://sciurus17_description/meshes/visual/L_HandA.stl" scale="1.0 1.0 1.0"/>
      </geometry>
      <material name="red_color">
        <color rgba="0.8984375 0.0 0.0703125 1"/>
      </material>
    </visual>
    <collision>
      <origin rpy="0 0 0" xyz="0.0 0.0 0.0"/>
      <geometry>
        <mesh filename="package://sciurus17_description/meshes/collision/L_HandA.stl" scale="1.0 1.0 1.0"/>
      </geometry>
    </collision>
    <inertial>
      <origin rpy="0 0 0" xyz="0.000425 -0.000896 0.018691"/>
      <inertia ixx="1.0" ixy="0.0" ixz="0.0" iyx="0.0" iyy="1.0" iyz="0.0" izx="0.0" izy="0.0" izz="1.0"/>
      <mass value="0.119807"/>
    </inertial>
  </link>
  <link name="l_handB_link">
    <visual>
      <origin rpy="0 0 0" xyz="0.0 0.0 0.0"/>
      <geometry>
        <mesh filename="package://sciurus17_description/meshes/visual/L_HandB.stl" scale="1.0 1.0 1.0"/>
      </geometry>
      <material name="red_color">
        <color rgba="0.8984375 0.0 0.0703125 1"/>
      </material>
    </visual>
    <collision>
      <origin rpy="0 0 0" xyz="0.0 0.0 0.0"/>
      <geometry>
        <mesh filename="package://sciurus17_description/meshes/collision/L_HandB.stl" scale="1.0 1.0 1.0"/>
      </geometry>
    </collision>
    <inertial>
      <origin rpy="0 0 0" xyz="0.000425 -0.000896 0.018691"/>
      <inertia ixx="1.0" ixy="0.0" ixz="0.0" iyx="0.0" iyy="1.0" iyz="0.0" izx="0.0" izy="0.0" izz="1.0"/>
      <mass value="0.119807"/>
    </inertial>
  </link>

  <!--gazebo>
    <plugin filename="libgazebo_ros_control.so" name="gazebo_ros_control">
      <robotNamespace>sciurus17</robotNamespace>
    </plugin>
  </gazebo-->

  <joint name="waist_yaw_joint" type="revolute">
    <parent link="base_link" />
    <child link="body_link" />
    <origin xyz="0.0 0.0 0.1315" rpy="0 0 0"/>
    <limit lower="-1.919862" upper="1.919862" effort="4.0" velocity="5.969211435"/>
    <axis xyz="0 0 1"/>
  </joint>
  <joint name="neck_yaw_joint" type="revolute">
    <parent link="body_link" />
    <child link="neck_yaw_link" />
    <origin xyz="0.08083 0.0 0.3395" rpy="0 0 0"/>
    <limit lower="-2.879793" upper="2.879793" effort="4.0" velocity="5.969211435"/>
    <axis xyz="0 0 1"/>
  </joint>
  <joint name="neck_pitch_joint" type="revolute">
    <parent link="neck_yaw_link" />
    <child link="neck_pitch_link" />
    <origin xyz="0.0 0.0 0.054" rpy="0 0 0"/>
    <limit lower="-1.570796" upper="1.570796" effort="4.0" velocity="5.969211435"/>
    <axis xyz="0 -1 0"/>
  </joint>
  <joint name="head_camera_joint" type="fixed">
    <parent link="neck_pitch_link" />
    <child link="camera_link" />
    <origin xyz="0.081785 0.03522 0.091" rpy="0 0 0"/>
  </joint>
  <joint name="chest_camera_joint" type="fixed">
    <parent link="body_link" />
    <child link="chest_camera_link" />
    <origin xyz="0.114576 0.0 0.217659" rpy="-2.7925268032 0 -1.5707963268"/>
  </joint>
  <joint name="r_arm_joint1" type="revolute">
    <parent link="body_link" />
    <child link="r_link1" />
    <origin xyz="0.08083 -0.0965 0.2885" rpy="0 0 0"/>
    <limit lower="-1.5707963268" upper="1.5707963268" effort="4.0" velocity="5.969211435"/>
    <axis xyz="0 -1 0"/>
  </joint>
  <joint name="r_arm_joint2" type="revolute">
    <parent link="r_link1" />
    <child link="r_link2" />
    <origin xyz="0.0 -0.064 0.0" rpy="0 0 0"/>
    <limit lower="-1.570796" upper="0.0" effort="4.0" velocity="5.969211435"/>
    <axis xyz="-1 0 0"/>
  </joint>
  <joint name="r_arm_joint3" type="revolute">
    <parent link="r_link2" />
    <child link="r_link3" />
    <origin xyz="0.0 -0.065 0.0" rpy="0 0 0"/>
    <limit lower="-1.5707963268" upper="1.5707963268" effort="4.0" velocity="5.969211435"/>
    <axis xyz="0 -1 0"/>
  </joint>
  <joint name="r_arm_joint4" type="revolute">
    <parent link="r_link3" />
    <child link="r_link4" />
    <origin xyz="0.0 -0.185 0.0" rpy="0 0 0"/>
    <limit lower="0.0" upper="2.726204" effort="4.0" velocity="5.969211435"/>
    <axis xyz="0 0 1"/>
  </joint>
  <joint name="r_arm_joint5" type="revolute">
    <parent link="r_link4" />
    <child link="r_link5" />
    <origin xyz="0.0 -0.121 0.0" rpy="0 0 0"/>
    <limit lower="-1.5707963268" upper="1.5707963268" effort="4.0" velocity="5.969211435"/>
    <axis xyz="0 -1 0"/>
  </joint>
  <joint name="r_arm_armarker" type="fixed">
    <parent link="r_link5" />
    <child link="r_link5_armarker" />
    <origin xyz="0.0467 -0.093 0.0" rpy="0 0 0"/>
  </joint>
  <joint name="r_arm_joint6" type="revolute">
    <parent link="r_link5" />
    <child link="r_link6" />
    <origin xyz="0.0 -0.129 0.0" rpy="0 0 0"/>
    <limit lower="-2.094395" upper="1.047196" effort="4.0" velocity="5.969211435"/>
    <axis xyz="0 0 1"/>
  </joint>
  <joint name="r_arm_joint7" type="revolute">
    <parent link="r_link6" />
    <child link="r_link7" />
    <origin xyz="0.0 -0.0191 0.0" rpy="0 0 0"/>
    <limit lower="-2.967060" upper="2.967060" effort="4.0" velocity="5.969211435"/>
    <axis xyz="0 -1 0"/>
  </joint>
  <joint name="r_hand_joint" type="revolute">
    <parent link="r_link7" />
    <child link="r_handA_link" />
    <origin xyz="0.012 -0.024 0.0" rpy="0 0 0"/>
    <limit lower="0.0" upper="1.5" effort="4.0" velocity="5.969211435"/>
    <axis xyz="0 0 1"/>
  </joint>
  <joint name="r_hand_mimic_joint" type="revolute">
    <parent link="r_link7" />
    <child link="r_handB_link" />
    <origin xyz="-0.012 -0.024 0.0" rpy="0 0 0"/>
    <limit lower="0.0" upper="1.5" effort="4.0" velocity="5.969211435"/>
    <axis xyz="0 0 1"/>
    <mimic joint="r_hand_joint" multiplier="-1" offset="0"/>
  </joint>

  <joint name="l_arm_joint1" type="revolute">
    <parent link="body_link" />
    <child link="l_link1" />
    <origin xyz="0.08083 0.0965 0.2885" rpy="0 0 0"/>
    <limit lower="-1.5707963268" upper="1.5707963268" effort="4.0" velocity="5.969211435"/>
    <axis xyz="0 1 0"/>
  </joint>
  <joint name="l_arm_joint2" type="revolute">
    <parent link="l_link1" />
    <child link="l_link2" />
    <origin xyz="0.0 0.064 0.0" rpy="0 0 0"/>
    <limit lower="0.0" upper="1.570796" effort="4.0" velocity="5.969211435"/>
    <axis xyz="-1 0 0"/>
  </joint>
  <joint name="l_arm_joint3" type="revolute">
    <parent link="l_link2" />
    <child link="l_link3" />
    <origin xyz="0.0 0.065 0.0" rpy="0 0 0"/>
    <limit lower="-1.5707963268" upper="1.5707963268" effort="4.0" velocity="5.969211435"/>
    <axis xyz="0 1 0"/>
  </joint>
  <joint name="l_arm_joint4" type="revolute">
    <parent link="l_link3" />
    <child link="l_link4" />
    <origin xyz="0.0 0.185 0.0" rpy="0 0 0"/>
    <limit lower="-2.726204" upper="0.000000" effort="4.0" velocity="5.969211435"/>
    <axis xyz="0 0 1"/>
  </joint>
  <joint name="l_arm_joint5" type="revolute">
    <parent link="l_link4" />
    <child link="l_link5" />
    <origin xyz="0.0 0.121 0.0" rpy="0 0 0"/>
    <limit lower="-1.5707963268" upper="1.5707963268" effort="4.0" velocity="5.969211435"/>
    <axis xyz="0 1 0"/>
  </joint>
  <joint name="l_arm_armarker" type="fixed">
    <parent link="l_link5" />
    <child link="l_link5_armarker" />
    <origin xyz="0.0467 0.093 0.0" rpy="0 0 0"/>
  </joint>
  <joint name="l_arm_joint6" type="revolute">
    <parent link="l_link5" />
    <child link="l_link6" />
    <origin xyz="0.0 0.129 0.0" rpy="0 0 0"/>
    <limit lower="-1.047198" upper="2.094395" effort="4.0" velocity="5.969211435"/>
    <axis xyz="0 0 1"/>
  </joint>
  <joint name="l_arm_joint7" type="revolute">
    <parent link="l_link6" />
    <child link="l_link7" />
    <origin xyz="0.0 0.0191 0.0" rpy="0 0 0"/>
    <limit lower="-2.967060" upper="2.967060" effort="4.0" velocity="5.969211435"/>
    <axis xyz="0 1 0"/>
  </joint>
  <joint name="l_hand_joint" type="revolute">
    <parent link="l_link7" />
    <child link="l_handA_link" />
    <origin xyz="0.012 0.024 0.0" rpy="0 0 0"/>
    <limit lower="-1.5" upper="0.0" effort="4.0" velocity="5.969211435"/>
    <axis xyz="0 0 1"/>
  </joint>
  <joint name="l_hand_mimic_joint" type="revolute">
    <parent link="l_link7" />
    <child link="l_handB_link" />
    <origin xyz="-0.012 0.024 0.0" rpy="0 0 0"/>
    <limit lower="-1.5" upper="0.0" effort="4.0" velocity="5.969211435"/>
    <axis xyz="0 0 1"/>
    <mimic joint="l_hand_joint" multiplier="-1" offset="0"/>
  </joint>

  <transmission name="waist_yaw_joint_trans">
    <provideFeedback>true</provideFeedback>
    <implicitSpringDamper>1</implicitSpringDamper>
    <motorTorqueConstant>0.418</motorTorqueConstant>
    <type>transmission_interface/SimpleTransmission</type>
    <joint name="waist_yaw_joint">
      <hardwareInterface>hardware_interface/PositionJointInterface</hardwareInterface>
    </joint>
    <actuator name="18">
      <hardwareInterface>hardware_interface/PositionJointInterface</hardwareInterface>
      <mechanicalReduction>1</mechanicalReduction>
    </actuator>
  </transmission>
  <transmission name="neck_pitch_joint_trans">
    <provideFeedback>true</provideFeedback>
    <implicitSpringDamper>1</implicitSpringDamper>
    <motorTorqueConstant>0.418</motorTorqueConstant>
    <type>transmission_interface/SimpleTransmission</type>
    <joint name="neck_pitch_joint">
      <hardwareInterface>hardware_interface/PositionJointInterface</hardwareInterface>
    </joint>
    <actuator name="19">
      <hardwareInterface>hardware_interface/PositionJointInterface</hardwareInterface>
      <mechanicalReduction>1</mechanicalReduction>
    </actuator>
  </transmission>
  <transmission name="neck_yaw_joint_trans">
    <provideFeedback>true</provideFeedback>
    <implicitSpringDamper>1</implicitSpringDamper>
    <motorTorqueConstant>0.418</motorTorqueConstant>
    <type>transmission_interface/SimpleTransmission</type>
    <joint name="neck_yaw_joint">
      <hardwareInterface>hardware_interface/PositionJointInterface</hardwareInterface>
    </joint>
    <actuator name="20">
      <hardwareInterface>hardware_interface/PositionJointInterface</hardwareInterface>
      <mechanicalReduction>1</mechanicalReduction>
    </actuator>
  </transmission>
  <transmission name="r_arm_joint1_trans">
    <provideFeedback>true</provideFeedback>
    <implicitSpringDamper>1</implicitSpringDamper>
    <motorTorqueConstant>0.418</motorTorqueConstant>
    <type>transmission_interface/SimpleTransmission</type>
    <joint name="r_arm_joint1">
      <hardwareInterface>hardware_interface/PositionJointInterface</hardwareInterface>
    </joint>
    <actuator name="2">
      <hardwareInterface>hardware_interface/PositionJointInterface</hardwareInterface>
      <mechanicalReduction>1</mechanicalReduction>
    </actuator>
  </transmission>
  <transmission name="r_arm_joint2_trans">
    <provideFeedback>true</provideFeedback>
    <implicitSpringDamper>1</implicitSpringDamper>
    <motorTorqueConstant>0.418</motorTorqueConstant>
    <type>transmission_interface/SimpleTransmission</type>
    <joint name="r_arm_joint2">
      <hardwareInterface>hardware_interface/PositionJointInterface</hardwareInterface>
    </joint>
    <actuator name="3">
      <hardwareInterface>hardware_interface/PositionJointInterface</hardwareInterface>
      <mechanicalReduction>1</mechanicalReduction>
    </actuator>
  </transmission>
  <transmission name="r_arm_joint3_trans">
    <provideFeedback>true</provideFeedback>
    <implicitSpringDamper>1</implicitSpringDamper>
    <motorTorqueConstant>0.418</motorTorqueConstant>
    <type>transmission_interface/SimpleTransmission</type>
    <joint name="r_arm_joint3">
      <hardwareInterface>hardware_interface/PositionJointInterface</hardwareInterface>
    </joint>
    <actuator name="4">
      <hardwareInterface>hardware_interface/PositionJointInterface</hardwareInterface>
      <mechanicalReduction>1</mechanicalReduction>
    </actuator>
  </transmission>
  <transmission name="r_arm_joint4_trans">
    <provideFeedback>true</provideFeedback>
    <implicitSpringDamper>1</implicitSpringDamper>
    <motorTorqueConstant>0.418</motorTorqueConstant>
    <type>transmission_interface/SimpleTransmission</type>
    <joint name="r_arm_joint4">
      <hardwareInterface>hardware_interface/PositionJointInterface</hardwareInterface>
    </joint>
    <actuator name="5">
      <hardwareInterface>hardware_interface/PositionJointInterface</hardwareInterface>
      <mechanicalReduction>1</mechanicalReduction>
    </actuator>
  </transmission>
  <transmission name="r_arm_joint5_trans">
    <provideFeedback>true</provideFeedback>
    <implicitSpringDamper>1</implicitSpringDamper>
    <motorTorqueConstant>0.418</motorTorqueConstant>
    <type>transmission_interface/SimpleTransmission</type>
    <joint name="r_arm_joint5">
      <hardwareInterface>hardware_interface/PositionJointInterface</hardwareInterface>
    </joint>
    <actuator name="6">
      <hardwareInterface>hardware_interface/PositionJointInterface</hardwareInterface>
      <mechanicalReduction>1</mechanicalReduction>
    </actuator>
  </transmission>
  <transmission name="r_arm_joint6_trans">
    <provideFeedback>true</provideFeedback>
    <implicitSpringDamper>1</implicitSpringDamper>
    <motorTorqueConstant>0.418</motorTorqueConstant>
    <type>transmission_interface/SimpleTransmission</type>
    <joint name="r_arm_joint6">
      <hardwareInterface>hardware_interface/PositionJointInterface</hardwareInterface>
    </joint>
    <actuator name="7">
      <hardwareInterface>hardware_interface/PositionJointInterface</hardwareInterface>
      <mechanicalReduction>1</mechanicalReduction>
    </actuator>
  </transmission>
  <transmission name="r_arm_joint7_trans">
    <provideFeedback>true</provideFeedback>
    <implicitSpringDamper>1</implicitSpringDamper>
    <motorTorqueConstant>0.418</motorTorqueConstant>
    <type>transmission_interface/SimpleTransmission</type>
    <joint name="r_arm_joint7">
      <hardwareInterface>hardware_interface/PositionJointInterface</hardwareInterface>
    </joint>
    <actuator name="8">
      <hardwareInterface>hardware_interface/PositionJointInterface</hardwareInterface>
      <mechanicalReduction>1</mechanicalReduction>
    </actuator>
  </transmission>
  <transmission name="r_hand_joint_trans">
    <provideFeedback>true</provideFeedback>
    <implicitSpringDamper>1</implicitSpringDamper>
    <motorTorqueConstant>0.418</motorTorqueConstant>
    <type>transmission_interface/SimpleTransmission</type>
    <joint name="r_hand_joint">
      <hardwareInterface>hardware_interface/PositionJointInterface</hardwareInterface>
    </joint>
    <actuator name="9">
      <hardwareInterface>hardware_interface/PositionJointInterface</hardwareInterface>
      <mechanicalReduction>1</mechanicalReduction>
    </actuator>
  </transmission>

  <transmission name="l_arm_joint1_trans">
    <provideFeedback>true</provideFeedback>
    <implicitSpringDamper>1</implicitSpringDamper>
    <motorTorqueConstant>0.418</motorTorqueConstant>
    <type>transmission_interface/SimpleTransmission</type>
    <joint name="l_arm_joint1">
      <hardwareInterface>hardware_interface/PositionJointInterface</hardwareInterface>
    </joint>
    <actuator name="10">
      <hardwareInterface>hardware_interface/PositionJointInterface</hardwareInterface>
      <mechanicalReduction>1</mechanicalReduction>
    </actuator>
  </transmission>
  <transmission name="l_arm_joint2_trans">
    <provideFeedback>true</provideFeedback>
    <implicitSpringDamper>1</implicitSpringDamper>
    <motorTorqueConstant>0.418</motorTorqueConstant>
    <type>transmission_interface/SimpleTransmission</type>
    <joint name="l_arm_joint2">
      <hardwareInterface>hardware_interface/PositionJointInterface</hardwareInterface>
    </joint>
    <actuator name="11">
      <hardwareInterface>hardware_interface/PositionJointInterface</hardwareInterface>
      <mechanicalReduction>1</mechanicalReduction>
    </actuator>
  </transmission>
  <transmission name="l_arm_joint3_trans">
    <provideFeedback>true</provideFeedback>
    <implicitSpringDamper>1</implicitSpringDamper>
    <motorTorqueConstant>0.418</motorTorqueConstant>
    <type>transmission_interface/SimpleTransmission</type>
    <joint name="l_arm_joint3">
      <hardwareInterface>hardware_interface/PositionJointInterface</hardwareInterface>
    </joint>
    <actuator name="12">
      <hardwareInterface>hardware_interface/PositionJointInterface</hardwareInterface>
      <mechanicalReduction>1</mechanicalReduction>
    </actuator>
  </transmission>
  <transmission name="l_arm_joint4_trans">
    <provideFeedback>true</provideFeedback>
    <implicitSpringDamper>1</implicitSpringDamper>
    <motorTorqueConstant>0.418</motorTorqueConstant>
    <type>transmission_interface/SimpleTransmission</type>
    <joint name="l_arm_joint4">
      <hardwareInterface>hardware_interface/PositionJointInterface</hardwareInterface>
    </joint>
    <actuator name="13">
      <hardwareInterface>hardware_interface/PositionJointInterface</hardwareInterface>
      <mechanicalReduction>1</mechanicalReduction>
    </actuator>
  </transmission>
  <transmission name="l_arm_joint5_trans">
    <provideFeedback>true</provideFeedback>
    <implicitSpringDamper>1</implicitSpringDamper>
    <motorTorqueConstant>0.418</motorTorqueConstant>
    <type>transmission_interface/SimpleTransmission</type>
    <joint name="l_arm_joint5">
      <hardwareInterface>hardware_interface/PositionJointInterface</hardwareInterface>
    </joint>
    <actuator name="14">
      <hardwareInterface>hardware_interface/PositionJointInterface</hardwareInterface>
      <mechanicalReduction>1</mechanicalReduction>
    </actuator>
  </transmission>
  <transmission name="l_arm_joint6_trans">
    <provideFeedback>true</provideFeedback>
    <implicitSpringDamper>1</implicitSpringDamper>
    <motorTorqueConstant>0.418</motorTorqueConstant>
    <type>transmission_interface/SimpleTransmission</type>
    <joint name="l_arm_joint6">
      <hardwareInterface>hardware_interface/PositionJointInterface</hardwareInterface>
    </joint>
    <actuator name="15">
      <hardwareInterface>hardware_interface/PositionJointInterface</hardwareInterface>
      <mechanicalReduction>1</mechanicalReduction>
    </actuator>
  </transmission>
  <transmission name="l_arm_joint7_trans">
    <provideFeedback>true</provideFeedback>
    <implicitSpringDamper>1</implicitSpringDamper>
    <motorTorqueConstant>0.418</motorTorqueConstant>
    <type>transmission_interface/SimpleTransmission</type>
    <joint name="l_arm_joint7">
      <hardwareInterface>hardware_interface/PositionJointInterface</hardwareInterface>
    </joint>
    <actuator name="16">
      <hardwareInterface>hardware_interface/PositionJointInterface</hardwareInterface>
      <mechanicalReduction>1</mechanicalReduction>
    </actuator>
  </transmission>
  <transmission name="l_hand_joint_trans">
    <provideFeedback>true</provideFeedback>
    <implicitSpringDamper>1</implicitSpringDamper>
    <motorTorqueConstant>0.418</motorTorqueConstant>
    <type>transmission_interface/SimpleTransmission</type>
    <joint name="l_hand_joint">
      <hardwareInterface>hardware_interface/PositionJointInterface</hardwareInterface>
    </joint>
    <actuator name="17">
      <hardwareInterface>hardware_interface/PositionJointInterface</hardwareInterface>
      <mechanicalReduction>1</mechanicalReduction>
    </actuator>
  </transmission>

  <gazebo reference="camera_link">
      <sensor type="depth" name="openni_camera_camera">       
          <always_on>1</always_on>
          <visualize>true</visualize>             
          <camera>
              <horizontal_fov>1.047</horizontal_fov>  
              <image>
                  <width>640</width>
                  <height>480</height>
                  <format>R8G8B8</format>
              </image>
              <depth_camera>
              </depth_camera>
              <clip>
                  <near>0.1</near>
                  <far>100</far>
              </clip>
          </camera>
          <plugin name="camera_controller" filename="libgazebo_ros_openni_kinect.so">
              <robotNamespace>sciurus17</robotNamespace>
              <alwaysOn>true</alwaysOn>
                  <updateRate>10.0</updateRate>
                  <cameraName>camera</cameraName>
                  <frameName>openni_camera_link</frameName>                   
              <imageTopicName>rgb/image_raw</imageTopicName>
              <depthImageTopicName>depth/image_raw</depthImageTopicName>
              <pointCloudTopicName>depth/points</pointCloudTopicName>
              <cameraInfoTopicName>rgb/camera_info</cameraInfoTopicName>              
              <depthImageCameraInfoTopicName>depth/camera_info</depthImageCameraInfoTopicName>            
              <pointCloudCutoff>0.4</pointCloudCutoff>                
                  <hackBaseline>0.07</hackBaseline>
                  <distortionK1>0.0</distortionK1>
                  <distortionK2>0.0</distortionK2>
                  <distortionK3>0.0</distortionK3>
                  <distortionT1>0.0</distortionT1>
                  <distortionT2>0.0</distortionT2>
              <CxPrime>0.0</CxPrime>
              <Cx>0.0</Cx>
              <Cy>0.0</Cy>
              <focalLength>0.0</focalLength>
              </plugin>
      </sensor>
  </gazebo>
</robot>
