<?xml version="1.0" ?>
<robot name="sciurus17">
  <link name="base_link">
    <visual>
      <geometry>
        <mesh filename="package://sciurus17_description/meshes/visual/Base.stl" scale="1.0 1.0 1.0"/>
      </geometry>
      <material name="white_color">
        <color rgba="0.9 0.9 0.9 1"/>
      </material>
    </visual>
    <collision>
      <origin rpy="0 0 0" xyz="0.0 0.0 0.0"/>
      <geometry>
        <mesh filename="package://sciurus17_description/meshes/collision/Base.stl" scale="1.0 1.0 1.0"/>
      </geometry>
    </collision>
    <inertial>
      <origin rpy="0 0 0" xyz="-24.012e-03 0.139e-03 59.566e-03"/>
      <inertia ixx="6398092.663e-09" ixy="-6808.969e-09" ixz="-331509.04e-09" iyy="7611664.357e-09" iyz="2026.354e-09" izz="6331936.461e-09"/>
      <mass value="1722.937e-03"/>
    </inertial>
  </link>
  <link name="body_link">
    <visual>
      <geometry>
        <mesh filename="package://sciurus17_description/meshes/visual/Body.stl" scale="1.0 1.0 1.0"/>
      </geometry>
      <material name="white_color">
        <color rgba="0.9 0.9 0.9 1"/>
      </material>
    </visual>
    <collision>
      <origin rpy="0 0 0" xyz="0.0 0.0 0.0"/>
      <geometry>
        <mesh filename="package://sciurus17_description/meshes/collision/Body.stl" scale="1.0 1.0 1.0"/>
      </geometry>
    </collision>
    <inertial>
     <origin rpy="0 0 0" xyz="57.11e-03 0.372e-03 238.229e-03"/>
      <inertia ixx="15601031.58e-09" ixy="-15890.903e-09" ixz="-3805596.494e-09" iyy="13969734.5e-09" iyz="-20695.221e-09" izz="8327993.097e-09"/>
      <mass value="1482.929e-03"/>
    </inertial>
  </link>

  <link name="neck_pitch_link">
    <visual>
      <origin rpy="1.5708 0 0" xyz="0.0 0.0 0.0"/>
      <geometry>
        <mesh filename="package://sciurus17_description/meshes/visual/Neck2.stl" scale="1.0 1.0 1.0"/>
      </geometry>
      <material name="white_color"/>
    </visual>
    <collision>
      <origin rpy="1.5708 0 0" xyz="0.0 0.0 0.0"/>
      <geometry>
        <mesh filename="package://sciurus17_description/meshes/collision/Neck2.stl" scale="1.0 1.0 1.0"/>
      </geometry>
    </collision>
    <inertial>
      <origin rpy="1.5708 0 0" xyz="19.979e-03 -0.151e-03 78.687e-03"/>
      <inertia ixx="964350.46e-09" ixy="-56112.026e-09" ixz="-731.103e-09" iyy="1027677.585e-09" iyz="1684.659e-09" izz="1065891.198e-09"/>
      <mass value="312.172e-03"/>
    </inertial>
  </link>
  <link name="neck_yaw_link">
    <visual>
      <geometry>
        <mesh filename="package://sciurus17_description/meshes/visual/Neck1.stl" scale="1.0 1.0 1.0"/>
      </geometry>
      <material name="white_color"/>
    </visual>
    <collision>
      <geometry>
        <mesh filename="package://sciurus17_description/meshes/collision/Neck1.stl" scale="1.0 1.0 1.0"/>
      </geometry>
    </collision>
    <inertial>
      <origin rpy="0 0 0" xyz="-0.022e-03 0.029e-03 40.86e-03"/>
      <inertia ixx="63143.268e-09" ixy="-0.078e-09" ixz="-126.072e-09" iyy="66522.419e-09" iyz="187.375e-09" izz="32744.236e-09"/>
      <mass value="168.0e-03"/>
    </inertial>
  </link>
  <link name="camera_link">
    <visual>
      <origin xyz="0 0 0" rpy="0 0 0"/>
      <geometry>
        <cylinder length="0.002" radius="0.003"/>
      </geometry>
      <material name="white_color"/>
    </visual>
    <collision>
      <origin xyz="0.0 0.0 0.0" rpy="0 0 0"/>
      <geometry>
        <cylinder length="0.002" radius="0.003"/>
      </geometry>
    </collision>
  </link>
  <link name="chest_camera_link">
    <visual>
      <origin xyz="0 0 0" rpy="0 0 0"/>
      <geometry>
        <cylinder length="0.002" radius="0.003"/>
      </geometry>
      <material name="white_color"/>
    </visual>
    <collision>
      <origin xyz="0.0 0.0 0.0" rpy="0 0 0"/>
      <geometry>
        <cylinder length="0.002" radius="0.003"/>
      </geometry>
    </collision>
  </link>

  <link name="r_link1">
    <visual>
      <origin rpy="1.5708 0 0" xyz="0.0 0.0 0.0"/>
      <geometry>
        <mesh filename="package://sciurus17_description/meshes/visual/R_Link1.stl" scale="1.0 1.0 1.0"/>
      </geometry>
      <material name="white_color"/>
    </visual>
    <collision>
      <origin rpy="1.5708 0 0" xyz="0.0 0.0 0.0"/>
      <geometry>
        <mesh filename="package://sciurus17_description/meshes/collision/R_Link1.stl" scale="1.0 1.0 1.0"/>
      </geometry>
    </collision>
    <inertial>
      <origin rpy="1.5708 0 0" xyz="-0.656e-03 -46.367e-03 -0.264e-03"/>
      <inertia ixx="176217.476e-09" ixy="-5.425e-09" ixz="586.979e-09" iyy="179207.793e-09" iyz="-166.297e-09" izz="87950.071e-09"/>
      <mass value="258.0e-03"/>
    </inertial>
  </link>
  <link name="r_link2">
    <visual>
      <origin rpy="0 1.5708 0" xyz="0.0 0.0 0.0"/>
      <geometry>
        <mesh filename="package://sciurus17_description/meshes/visual/R_Link2.stl" scale="-1.0 1.0 1.0"/>
      </geometry>
      <material name="white_color"/>
    </visual>
    <collision>
      <origin rpy="0 1.5708 0" xyz="0.0 0.0 0.0"/>
      <geometry>
        <mesh filename="package://sciurus17_description/meshes/collision/R_Link2.stl" scale="-1.0 1.0 1.0"/>
      </geometry>
    </collision>
    <inertial>
      <origin rpy="0 1.5708 0" xyz="-0.185e-03 -33.96e-03 -0.033e-03"/>
      <inertia ixx="172046.031e-09" ixy="-119.176e-09" ixz="-535.109e-09" iyy="98834.156e-09" iyz="580.743e-09" izz="136915.218e-09"/>
      <mass value="134.0e-03"/>
    </inertial>
  </link>
  <link name="r_link3">
    <visual>
      <origin rpy="1.5708 0 0" xyz="0.0 0.0 0.0"/>
      <geometry>
        <mesh filename="package://sciurus17_description/meshes/visual/L_Link3.stl" scale="1.0 -1.0 1.0"/>
      </geometry>
      <material name="white_color"/>
    </visual>
    <collision>
      <origin rpy="1.5708 0 0" xyz="0.0 0.0 0.0"/>
      <geometry>
        <mesh filename="package://sciurus17_description/meshes/collision/L_Link3.stl" scale="1.0 -1.0 1.0"/>
      </geometry>
    </collision>
    <inertial>
      <origin rpy="1.5708 0 0" xyz="-13.791e-03 -113.391e-03 0.245e-03"/>
      <inertia ixx="2336253.636e-09" ixy="-1190.372e-09" ixz="-75998.279e-09" iyy="2414711.907e-09" iyz="-8024.912e-09" izz="236305.543e-09"/>
      <mass value="443.0e-03"/>
    </inertial>
  </link>
  <link name="r_link4">
    <visual>
      <origin rpy="0 0 0" xyz="0.0 0.0 0.0"/>
      <geometry>
        <mesh filename="package://sciurus17_description/meshes/visual/R_Link4.stl" scale="1.0 1.0 1.0"/>
      </geometry>
      <material name="white_color"/>
    </visual>
    <collision>
      <origin rpy="0 0 0" xyz="0.0 0.0 0.0"/>
      <geometry>
        <mesh filename="package://sciurus17_description/meshes/collision/R_Link4.stl" scale="1.0 1.0 1.0"/>
      </geometry>
    </collision>
    <inertial>
      <origin rpy="0 0 0" xyz="-8.881e-03 -75.749e-03 0.038e-03"/>
      <inertia ixx="603280.74e-09" ixy="-6670.94e-09" ixz="250.846e-09" iyy="143154.3e-09" iyz="-2309.247e-09" izz="598152.333e-09"/>
      <mass value="238.0e-03"/>
    </inertial>
  </link>
  <link name="r_link5">
    <visual>
      <origin rpy="1.5708 0 0" xyz="0.0 0.0 0.0"/>
      <geometry>
        <mesh filename="package://sciurus17_description/meshes/visual/R_Link5.stl" scale="1.0 1.0 1.0"/>
      </geometry>
      <material name="white_color"/>
    </visual>
    <visual>
      <origin xyz="0.032 -0.074 0.0345" rpy="0 0 -2.0944"/>
      <geometry>
        <mesh filename="package://sciurus17_description/meshes/visual/Logo_Rabbit.stl" scale="1.0 1.0 1.0"/>
      </geometry>
      <material name="red_color">
        <color rgba="0.8984375 0.0 0.0703125 1"/>
      </material>
    </visual>
    <visual>
      <origin xyz="0.013 -0.107 0.0345" rpy="0 0 -2.0944"/>
      <geometry>
        <mesh filename="package://sciurus17_description/meshes/visual/Logo_Corp.stl" scale="1.0 1.0 1.0"/>
      </geometry>
      <material name="black_color">
        <color rgba="0.2 0.2 0.2 1"/>
      </material>
    </visual>
    <collision>
      <origin rpy="1.5708 0 0" xyz="0.0 0.0 0.0"/>
      <geometry>
        <mesh filename="package://sciurus17_description/meshes/collision/R_Link5.stl" scale="1.0 1.0 1.0"/>
      </geometry>
    </collision>
    <inertial>
      <origin rpy="1.5708 0 0" xyz="13.531e-03 -70.369e-03 -0.304e-03"/>
      <inertia ixx="294726.731e-09" ixy="-4809.196e-09" ixz="-21387.985e-09" iyy="290568.087e-09" iyz="13192.269e-09" izz="125378.656e-09"/>
      <mass value="224.0e-03"/>
    </inertial>
  </link>
  <link name="r_link5_armarker">
    <visual>
      <origin rpy="0 0 0" xyz="0.0 0.0 0.0"/>
      <geometry>
        <cylinder length="0.001" radius="0.001"/>
      </geometry>
      <material name="white_color"/>
    </visual>
  </link>
  <link name="r_link6">
    <visual>
      <origin rpy="0 0 0" xyz="0.0 0.0 0.0"/>
      <geometry>
        <mesh filename="package://sciurus17_description/meshes/visual/R_Link6.stl" scale="1.0 1.0 1.0"/>
      </geometry>
      <material name="white_color"/>
    </visual>
    <collision>
      <origin rpy="0 0 0" xyz="0.0 0.0 0.0"/>
      <geometry>
        <mesh filename="package://sciurus17_description/meshes/collision/R_Link6.stl" scale="1.0 1.0 1.0"/>
      </geometry>
    </collision>
    <inertial>
      <origin rpy="0 0 0" xyz="-6.156e-03 3.583e-03 0.755e-03"/>
      <inertia ixx="39499.661e-09" ixy="-2921.88e-09" ixz="-612.042e-09" iyy="60684.342e-09" iyz="357.397e-09" izz="73112.015e-09"/>
      <mass value="140.0e-03"/>
    </inertial>
  </link>
  <link name="r_link7">
    <visual>
      <origin rpy="1.5708 0 0" xyz="0.0 0.0 0.0"/>
      <geometry>
        <mesh filename="package://sciurus17_description/meshes/visual/R_Link7.stl" scale="1.0 1.0 1.0"/>
      </geometry>
      <material name="red_color">
        <color rgba="0.8984375 0.0 0.0703125 1"/>
      </material>
    </visual>
    <collision>
      <origin rpy="1.5708 0 0" xyz="0.0 0.0 0.0"/>
      <geometry>
        <mesh filename="package://sciurus17_description/meshes/collision/R_Link7.stl" scale="1.0 1.0 1.0"/>
      </geometry>
    </collision>
    <inertial>
      <origin rpy="1.5708 0 0" xyz="-0.118e-03 -20.65e-03 1.006e-03"/>
      <inertia ixx="32600.928e-09" ixy="-69.84e-09" ixz="-254.224e-09" iyy="41969.484e-09" iyz="-409.16e-09" izz="43040.018e-09"/>
      <mass value="121.0e-03"/>
    </inertial>
  </link>
  <link name="r_handA_link">
    <visual>
      <!--origin rpy="3.14159 0 0" xyz="0.0 0.0 0.0"/-->
      <origin rpy="0 0 0" xyz="0.0 0.0 0.0"/>
      <geometry>
        <mesh filename="package://sciurus17_description/meshes/visual/R_HandA.stl" scale="1.0 1.0 1.0"/>
      </geometry>
      <material name="red_color">
        <color rgba="0.8984375 0.0 0.0703125 1"/>
      </material>
    </visual>
    <collision>
      <origin rpy="0 0 0" xyz="0.0 0.0 0.0"/>
      <geometry>
        <mesh filename="package://sciurus17_description/meshes/collision/R_HandA.stl" scale="1.0 1.0 1.0"/>
      </geometry>
    </collision>
    <inertial>
      <origin rpy="0 0 0" xyz="2.649e-03 -26.849e-03 3.757e-03"/>
      <inertia ixx="10192.75e-09" ixy="-197.895e-09" ixz="98.609e-09" iyy="5023.728e-09" iyz="-554.407e-09" izz="6322.202e-09"/>
      <mass value="15.8e-03"/>
    </inertial>
  </link>
  <link name="r_handB_link">
    <visual>
      <!-- origin rpy="3.14159 0 0" xyz="0.0 0.0 0.0"/ -->
      <origin rpy="0 0 0" xyz="0.0 0.0 0.0"/>
      <geometry>
        <mesh filename="package://sciurus17_description/meshes/visual/R_HandB.stl" scale="1.0 1.0 1.0"/>
      </geometry>
      <material name="red_color">
        <color rgba="0.8984375 0.0 0.0703125 1"/>
      </material>
    </visual>
    <collision>
      <origin rpy="0 0 0" xyz="0.0 0.0 0.0"/>
      <geometry>
        <mesh filename="package://sciurus17_description/meshes/collision/R_HandB.stl" scale="1.0 1.0 1.0"/>
      </geometry>
    </collision>
    <inertial>
      <origin rpy="0 0 0" xyz="-2.707e-03 -30.901e-03 2.845e-03"/>
      <inertia ixx="7483.7e-09" ixy="361.283e-09" ixz="-63.385e-09" iyy="4088.581e-09" iyz="-228.226e-09" izz="4372.991e-09"/>
      <mass value="13.9e-03"/>
    </inertial>
  </link>

  <link name="l_link1">
    <visual>
      <origin rpy="-1.5708 0 0" xyz="0.0 0.0 0.0"/>
      <geometry>
        <mesh filename="package://sciurus17_description/meshes/visual/L_Link1.stl" scale="1.0 1.0 1.0"/>
      </geometry>
      <material name="white_color"/>
    </visual>
    <collision>
      <origin rpy="-1.5708 0 0" xyz="0.0 0.0 0.0"/>
      <geometry>
        <mesh filename="package://sciurus17_description/meshes/collision/L_Link1.stl" scale="1.0 1.0 1.0"/>
      </geometry>
    </collision>
    <inertial>
      <origin rpy="-1.5708 0 0" xyz="-0.537e-03 46.27e-03 -0.27e-03"/>
      <inertia ixx="170007.992e-09" ixy="13.313e-09" ixz="454.301e-09" iyy="175079.881e-09" iyz="159.916e-09" izz="85282.27e-09"/>
      <mass value="258.0e-03"/>
    </inertial>
  </link>
  <link name="l_link2">
    <visual>
      <origin rpy="0 -1.5708 0" xyz="0.0 0.0 0.0"/>
      <geometry>
        <mesh filename="package://sciurus17_description/meshes/visual/L_Link2.stl" scale="1.0 1.0 -1.0"/>
      </geometry>
      <material name="white_color"/>
    </visual>
    <collision>
      <origin rpy="0 -1.5708 0" xyz="0.0 0.0 0.0"/>
      <geometry>
        <mesh filename="package://sciurus17_description/meshes/collision/L_Link2.stl" scale="1.0 1.0 -1.0"/>
      </geometry>
    </collision>
    <inertial>
      <origin rpy="0 -1.5708 0" xyz="0.199e-03 33.946e-03 -0.07e-03"/>
      <inertia ixx="172421.741e-09" ixy="-98.964e-09" ixz="-266.684e-09" iyy="99076.413e-09" iyz="-418.743e-09" izz="137151.205e-09"/>
      <mass value="134.0e-03"/>
    </inertial>
  </link>
  <link name="l_link3">
    <visual>
      <origin rpy="-1.5708 0 0" xyz="0.0 0.0 0.0"/>
      <geometry>
        <mesh filename="package://sciurus17_description/meshes/visual/L_Link3.stl" scale="1.0 1.0 1.0"/>
      </geometry>
      <material name="white_color"/>
    </visual>
    <collision>
      <origin rpy="-1.5708 0 0" xyz="0.0 0.0 0.0"/>
      <geometry>
        <mesh filename="package://sciurus17_description/meshes/collision/L_Link3.stl" scale="1.0 1.0 1.0"/>
      </geometry>
    </collision>
    <inertial>
      <origin rpy="-1.5708 0 0" xyz="-13.943e-03 113.533e-03 0.241e-03"/>
      <inertia ixx="2343035.312e-09" ixy="1178.732e-09" ixz="-72414.462e-09" iyy="2422253.94e-09" iyz="8074.759e-09" izz="237122.927e-09"/>
      <mass value="443.0e-03"/>
    </inertial>
  </link>
  <link name="l_link4">
    <visual>
      <origin rpy="0 0 0" xyz="0.0 0.0 0.0"/>
      <geometry>
        <mesh filename="package://sciurus17_description/meshes/visual/L_Link4.stl" scale="1.0 1.0 1.0"/>
      </geometry>
      <material name="white_color"/>
    </visual>
    <collision>
      <origin rpy="0 0 0" xyz="0.0 0.0 0.0"/>
      <geometry>
        <mesh filename="package://sciurus17_description/meshes/collision/L_Link4.stl" scale="1.0 1.0 1.0"/>
      </geometry>
    </collision>
    <inertial>
      <origin rpy="0 0 0" xyz="-8.926e-03 78.626e-03 -0.005e-03"/>
      <inertia ixx="533003.24e-09" ixy="972.381e-09" ixz="220.273e-09" iyy="130793.897e-09" iyz="1226.699e-09" izz="533022.145e-09"/>
      <mass value="238.0e-03"/>
    </inertial>
  </link>
  <link name="l_link5">
    <visual>
      <origin rpy="-1.5708 0 0" xyz="0.0 0.0 0.0"/>
      <geometry>
        <mesh filename="package://sciurus17_description/meshes/visual/L_Link5.stl" scale="1.0 1.0 1.0"/>
      </geometry>
      <material name="white_color"/>
    </visual>
    <visual>
      <origin xyz="0.032 0.074 -0.0346" rpy="3.1415926 0 2.0944"/>
      <geometry>
        <mesh filename="package://sciurus17_description/meshes/visual/Logo_Rabbit.stl" scale="1.0 1.0 1.0"/>
      </geometry>
      <material name="red_color">
        <color rgba="0.8984375 0.0 0.0703125 1"/>
      </material>
    </visual>
    <visual>
      <origin xyz="0.013 0.107 -0.0346" rpy="3.1415926 0 2.0944"/>
      <geometry>
        <mesh filename="package://sciurus17_description/meshes/visual/Logo_Corp.stl" scale="1.0 1.0 1.0"/>
      </geometry>
      <material name="black_color">
        <color rgba="0.2 0.2 0.2 1"/>
      </material>
    </visual>
    <collision>
      <origin rpy="-1.5708 0 0" xyz="0.0 0.0 0.0"/>
      <geometry>
        <mesh filename="package://sciurus17_description/meshes/collision/L_Link5.stl" scale="1.0 1.0 1.0"/>
      </geometry>
    </collision>
    <inertial>
      <origin rpy="-1.5708 0 0" xyz="13.732e-03 71.158e-03 -0.348e-03"/>
      <inertia ixx="286973.35e-09" ixy="4321.461e-09" ixz="-19101.45e-09" iyy="282370.572e-09" iyz="-13052.23e-09" izz="125680.836e-09"/>
      <mass value="224.0e-03"/>
    </inertial>
  </link>
  <link name="l_link5_armarker">
    <visual>
      <origin rpy="0 0 0" xyz="0.0 0.0 0.0"/>
      <geometry>
        <cylinder length="0.001" radius="0.001"/>
      </geometry>
      <material name="white_color"/>
    </visual>
  </link>
  <link name="l_link6">
    <visual>
      <origin rpy="0 0 0" xyz="0.0 0.0 0.0"/>
      <geometry>
        <mesh filename="package://sciurus17_description/meshes/visual/L_Link6.stl" scale="1.0 1.0 1.0"/>
      </geometry>
      <material name="white_color"/>
    </visual>
    <collision>
      <origin rpy="0 0 0" xyz="0.0 0.0 0.0"/>
      <geometry>
        <mesh filename="package://sciurus17_description/meshes/collision/L_Link6.stl" scale="1.0 1.0 1.0"/>
      </geometry>
    </collision>
    <inertial>
      <origin rpy="0 0 0" xyz="-6.173e-03 -3.627e-03 0.744e-03"/>
      <inertia ixx="39902.954e-09" ixy="3014.503e-09" ixz="-613.647e-09" iyy="61099.851e-09" iyz="-361.668e-09" izz="73723.447e-09"/>
      <mass value="140.0e-03"/>
    </inertial>
  </link>
  <link name="l_link7">
    <visual>
      <origin rpy="1.5708 0 0" xyz="0.0 0.0 0.0"/>
      <geometry>
        <mesh filename="package://sciurus17_description/meshes/visual/L_Link7.stl" scale="1.0 1.0 1.0"/>
      </geometry>
      <material name="red_color">
        <color rgba="0.8984375 0.0 0.0703125 1"/>
      </material>
    </visual>
    <collision>
      <origin rpy="1.5708 0 0" xyz="0.0 0.0 0.0"/>
      <geometry>
        <mesh filename="package://sciurus17_description/meshes/collision/L_Link7.stl" scale="1.0 1.0 1.0"/>
      </geometry>
    </collision>
    <inertial>
      <origin rpy="1.5708 0 0" xyz="-0.118e-03 20.65e-03 1.074e-03"/>
      <inertia ixx="32593.608e-09" ixy="-72.866e-09" ixz="254.224e-09" iyy="41969.484e-09" iyz="436.76e-09" izz="43032.698e-09"/>
      <mass value="121.0e-03"/>
    </inertial>
  </link>
  <link name="l_handA_link">
    <visual>
      <origin rpy="0 0 0" xyz="0.0 0.0 0.0"/>
      <geometry>
        <mesh filename="package://sciurus17_description/meshes/visual/L_HandA.stl" scale="1.0 1.0 1.0"/>
      </geometry>
      <material name="red_color">
        <color rgba="0.8984375 0.0 0.0703125 1"/>
      </material>
    </visual>
    <collision>
      <origin rpy="0 0 0" xyz="0.0 0.0 0.0"/>
      <geometry>
        <mesh filename="package://sciurus17_description/meshes/collision/L_HandA.stl" scale="1.0 1.0 1.0"/>
      </geometry>
    </collision>
    <inertial>
      <origin rpy="0 0 0" xyz="2.649e-03 26.849e-03 3.757e-03"/>
      <inertia ixx="10192.695e-09" ixy="197.91e-09" ixz="98.601e-09" iyy="5023.727e-09" iyz="554.38e-09" izz="6322.142e-09"/>
      <mass value="15.8e-03"/>
    </inertial>
  </link>
  <link name="l_handB_link">
    <visual>
      <origin rpy="0 0 0" xyz="0.0 0.0 0.0"/>
      <geometry>
        <mesh filename="package://sciurus17_description/meshes/visual/L_HandB.stl" scale="1.0 1.0 1.0"/>
      </geometry>
      <material name="red_color">
        <color rgba="0.8984375 0.0 0.0703125 1"/>
      </material>
    </visual>
    <collision>
      <origin rpy="0 0 0" xyz="0.0 0.0 0.0"/>
      <geometry>
        <mesh filename="package://sciurus17_description/meshes/collision/L_HandB.stl" scale="1.0 1.0 1.0"/>
      </geometry>
    </collision>
    <inertial>
      <origin rpy="0 0 0" xyz="-3.008e-03 30.851e-03 2.845e-03"/>
      <inertia ixx="7483.736e-09" ixy="-361.268e-09" ixz="-63.393e-09" iyy="4088.583e-09" iyz="228.245e-09" izz="4373.032e-09"/>
      <mass value="13.9e-03"/>
    </inertial>
  </link>

  <!--gazebo>
    <plugin filename="libgazebo_ros_control.so" name="gazebo_ros_control">
      <robotNamespace>sciurus17</robotNamespace>
    </plugin>
  </gazebo-->

 <joint name="waist_yaw_joint" type="revolute">
    <parent link="base_link" />
    <child link="body_link" />
    <origin xyz="0.0 0.0 0.1315" rpy="0 0 0"/>
    <limit lower="-1.919862" upper="1.919862" effort="4.0" velocity="5.969211435"/>
    <axis xyz="0 0 1"/>
  </joint>
  <joint name="neck_yaw_joint" type="revolute">
    <parent link="body_link" />
    <child link="neck_yaw_link" />
    <origin xyz="0.08083 0.0 0.3395" rpy="0 0 0"/>
    <limit lower="-2.879793" upper="2.879793" effort="4.0" velocity="5.969211435"/>
    <axis xyz="0 0 1"/>
  </joint>
  <joint name="neck_pitch_joint" type="revolute">
    <parent link="neck_yaw_link" />
    <child link="neck_pitch_link" />
    <origin xyz="0.0 0.0 0.054" rpy="0 0 0"/>
    <limit lower="-1.570796" upper="1.570796" effort="4.0" velocity="5.969211435"/>
    <axis xyz="0 -1 0"/>
  </joint>
  <joint name="head_camera_joint" type="fixed">
    <parent link="neck_pitch_link" />
    <child link="camera_link" />
    <origin xyz="0.081785 0.03522 0.091" rpy="0 0 0"/>
  </joint>
  <joint name="chest_camera_joint" type="fixed">
    <parent link="body_link" />
    <child link="chest_camera_link" />
    <origin xyz="0.114576 0.0 0.217659" rpy="-2.7925268032 0 -1.5707963268"/>
  </joint>
  <joint name="r_arm_joint1" type="revolute">
    <parent link="body_link" />
    <child link="r_link1" />
    <origin xyz="0.08083 -0.0965 0.2885" rpy="0 0 0"/>
    <limit lower="-1.5707963268" upper="1.5707963268" effort="4.0" velocity="5.969211435"/>
    <axis xyz="0 -1 0"/>
  </joint>
  <joint name="r_arm_joint2" type="revolute">
    <parent link="r_link1" />
    <child link="r_link2" />
    <origin xyz="0.0 -0.064 0.0" rpy="0 0 0"/>
    <limit lower="-1.570796" upper="0.0" effort="4.0" velocity="5.969211435"/>
    <axis xyz="-1 0 0"/>
  </joint>
  <joint name="r_arm_joint3" type="revolute">
    <parent link="r_link2" />
    <child link="r_link3" />
    <origin xyz="0.0 -0.065 0.0" rpy="0 0 0"/>
    <limit lower="-1.5707963268" upper="1.5707963268" effort="4.0" velocity="5.969211435"/>
    <axis xyz="0 -1 0"/>
  </joint>
  <joint name="r_arm_joint4" type="revolute">
    <parent link="r_link3" />
    <child link="r_link4" />
    <origin xyz="0.0 -0.185 0.0" rpy="0 0 0"/>
    <limit lower="0.0" upper="2.726204" effort="4.0" velocity="5.969211435"/>
    <axis xyz="0 0 1"/>
  </joint>
  <joint name="r_arm_joint5" type="revolute">
    <parent link="r_link4" />
    <child link="r_link5" />
    <origin xyz="0.0 -0.121 0.0" rpy="0 0 0"/>
    <limit lower="-1.5707963268" upper="1.5707963268" effort="4.0" velocity="5.969211435"/>
    <axis xyz="0 -1 0"/>
  </joint>
  <joint name="r_arm_armarker" type="fixed">
    <parent link="r_link5" />
    <child link="r_link5_armarker" />
    <origin xyz="0.0467 -0.093 0.0" rpy="0 0 0"/>
  </joint>
  <joint name="r_arm_joint6" type="revolute">
    <parent link="r_link5" />
    <child link="r_link6" />
    <origin xyz="0.0 -0.129 0.0" rpy="0 0 0"/>
    <limit lower="-2.094395" upper="1.047196" effort="4.0" velocity="5.969211435"/>
    <axis xyz="0 0 1"/>
  </joint>
  <joint name="r_arm_joint7" type="revolute">
    <parent link="r_link6" />
    <child link="r_link7" />
    <origin xyz="0.0 -0.0191 0.0" rpy="0 0 0"/>
    <limit lower="-2.967060" upper="2.967060" effort="4.0" velocity="5.969211435"/>
    <axis xyz="0 -1 0"/>
  </joint>
  <joint name="r_hand_joint" type="revolute">
    <parent link="r_link7" />
    <child link="r_handA_link" />
    <origin xyz="0.012 -0.024 0.0" rpy="0 0 0"/>
    <limit lower="0.0" upper="1.5" effort="4.0" velocity="5.969211435"/>
    <axis xyz="0 0 1"/>
  </joint>
  <joint name="r_hand_mimic_joint" type="revolute">
    <parent link="r_link7" />
    <child link="r_handB_link" />
    <origin xyz="-0.012 -0.024 0.0" rpy="0 0 0"/>
    <limit lower="0.0" upper="1.5" effort="4.0" velocity="5.969211435"/>
    <axis xyz="0 0 1"/>
    <mimic joint="r_hand_joint" multiplier="-1" offset="0"/>
  </joint>

  <joint name="l_arm_joint1" type="revolute">
    <parent link="body_link" />
    <child link="l_link1" />
    <origin xyz="0.08083 0.0965 0.2885" rpy="0 0 0"/>
    <limit lower="-1.5707963268" upper="1.5707963268" effort="4.0" velocity="5.969211435"/>
    <axis xyz="0 1 0"/>
  </joint>
  <joint name="l_arm_joint2" type="revolute">
    <parent link="l_link1" />
    <child link="l_link2" />
    <origin xyz="0.0 0.064 0.0" rpy="0 0 0"/>
    <limit lower="0.0" upper="1.570796" effort="4.0" velocity="5.969211435"/>
    <axis xyz="-1 0 0"/>
  </joint>
  <joint name="l_arm_joint3" type="revolute">
    <parent link="l_link2" />
    <child link="l_link3" />
    <origin xyz="0.0 0.065 0.0" rpy="0 0 0"/>
    <limit lower="-1.5707963268" upper="1.5707963268" effort="4.0" velocity="5.969211435"/>
    <axis xyz="0 1 0"/>
  </joint>
  <joint name="l_arm_joint4" type="revolute">
    <parent link="l_link3" />
    <child link="l_link4" />
    <origin xyz="0.0 0.185 0.0" rpy="0 0 0"/>
    <limit lower="-2.726204" upper="0.000000" effort="4.0" velocity="5.969211435"/>
    <axis xyz="0 0 1"/>
  </joint>
  <joint name="l_arm_joint5" type="revolute">
    <parent link="l_link4" />
    <child link="l_link5" />
    <origin xyz="0.0 0.121 0.0" rpy="0 0 0"/>
    <limit lower="-1.5707963268" upper="1.5707963268" effort="4.0" velocity="5.969211435"/>
    <axis xyz="0 1 0"/>
  </joint>
  <joint name="l_arm_armarker" type="fixed">
    <parent link="l_link5" />
    <child link="l_link5_armarker" />
    <origin xyz="0.0467 0.093 0.0" rpy="0 0 0"/>
  </joint>
  <joint name="l_arm_joint6" type="revolute">
    <parent link="l_link5" />
    <child link="l_link6" />
    <origin xyz="0.0 0.129 0.0" rpy="0 0 0"/>
    <limit lower="-1.047198" upper="2.094395" effort="4.0" velocity="5.969211435"/>
    <axis xyz="0 0 1"/>
  </joint>
  <joint name="l_arm_joint7" type="revolute">
    <parent link="l_link6" />
    <child link="l_link7" />
    <origin xyz="0.0 0.0191 0.0" rpy="0 0 0"/>
    <limit lower="-2.967060" upper="2.967060" effort="4.0" velocity="5.969211435"/>
    <axis xyz="0 1 0"/>
  </joint>
  <joint name="l_hand_joint" type="revolute">
    <parent link="l_link7" />
    <child link="l_handA_link" />
    <origin xyz="0.012 0.024 0.0" rpy="0 0 0"/>
    <limit lower="-1.5" upper="0.0" effort="4.0" velocity="5.969211435"/>
    <axis xyz="0 0 1"/>
  </joint>
  <joint name="l_hand_mimic_joint" type="revolute">
    <parent link="l_link7" />
    <child link="l_handB_link" />
    <origin xyz="-0.012 0.024 0.0" rpy="0 0 0"/>
    <limit lower="-1.5" upper="0.0" effort="4.0" velocity="5.969211435"/>
    <axis xyz="0 0 1"/>
    <mimic joint="l_hand_joint" multiplier="-1" offset="0"/>
  </joint>

  <transmission name="waist_yaw_joint_trans">
    <provideFeedback>true</provideFeedback>
    <implicitSpringDamper>1</implicitSpringDamper>
    <motorTorqueConstant>0.418</motorTorqueConstant>
    <type>transmission_interface/SimpleTransmission</type>
    <joint name="waist_yaw_joint">
      <hardwareInterface>hardware_interface/PositionJointInterface</hardwareInterface>
    </joint>
    <actuator name="18">
      <hardwareInterface>hardware_interface/PositionJointInterface</hardwareInterface>
      <mechanicalReduction>1</mechanicalReduction>
    </actuator>
  </transmission>
  <transmission name="neck_pitch_joint_trans">
    <provideFeedback>true</provideFeedback>
    <implicitSpringDamper>1</implicitSpringDamper>
    <motorTorqueConstant>0.418</motorTorqueConstant>
    <type>transmission_interface/SimpleTransmission</type>
    <joint name="neck_pitch_joint">
      <hardwareInterface>hardware_interface/PositionJointInterface</hardwareInterface>
    </joint>
    <actuator name="19">
      <hardwareInterface>hardware_interface/PositionJointInterface</hardwareInterface>
      <mechanicalReduction>1</mechanicalReduction>
    </actuator>
  </transmission>
  <transmission name="neck_yaw_joint_trans">
    <provideFeedback>true</provideFeedback>
    <implicitSpringDamper>1</implicitSpringDamper>
    <motorTorqueConstant>0.418</motorTorqueConstant>
    <type>transmission_interface/SimpleTransmission</type>
    <joint name="neck_yaw_joint">
      <hardwareInterface>hardware_interface/PositionJointInterface</hardwareInterface>
    </joint>
    <actuator name="20">
      <hardwareInterface>hardware_interface/PositionJointInterface</hardwareInterface>
      <mechanicalReduction>1</mechanicalReduction>
    </actuator>
  </transmission>
  <transmission name="r_arm_joint1_trans">
    <provideFeedback>true</provideFeedback>
    <implicitSpringDamper>1</implicitSpringDamper>
    <motorTorqueConstant>0.418</motorTorqueConstant>
    <type>transmission_interface/SimpleTransmission</type>
    <joint name="r_arm_joint1">
      <hardwareInterface>hardware_interface/PositionJointInterface</hardwareInterface>
    </joint>
    <actuator name="2">
      <hardwareInterface>hardware_interface/PositionJointInterface</hardwareInterface>
      <mechanicalReduction>1</mechanicalReduction>
    </actuator>
  </transmission>
  <transmission name="r_arm_joint2_trans">
    <provideFeedback>true</provideFeedback>
    <implicitSpringDamper>1</implicitSpringDamper>
    <motorTorqueConstant>0.418</motorTorqueConstant>
    <type>transmission_interface/SimpleTransmission</type>
    <joint name="r_arm_joint2">
      <hardwareInterface>hardware_interface/PositionJointInterface</hardwareInterface>
    </joint>
    <actuator name="3">
      <hardwareInterface>hardware_interface/PositionJointInterface</hardwareInterface>
      <mechanicalReduction>1</mechanicalReduction>
    </actuator>
  </transmission>
  <transmission name="r_arm_joint3_trans">
    <provideFeedback>true</provideFeedback>
    <implicitSpringDamper>1</implicitSpringDamper>
    <motorTorqueConstant>0.418</motorTorqueConstant>
    <type>transmission_interface/SimpleTransmission</type>
    <joint name="r_arm_joint3">
      <hardwareInterface>hardware_interface/PositionJointInterface</hardwareInterface>
    </joint>
    <actuator name="4">
      <hardwareInterface>hardware_interface/PositionJointInterface</hardwareInterface>
      <mechanicalReduction>1</mechanicalReduction>
    </actuator>
  </transmission>
  <transmission name="r_arm_joint4_trans">
    <provideFeedback>true</provideFeedback>
    <implicitSpringDamper>1</implicitSpringDamper>
    <motorTorqueConstant>0.418</motorTorqueConstant>
    <type>transmission_interface/SimpleTransmission</type>
    <joint name="r_arm_joint4">
      <hardwareInterface>hardware_interface/PositionJointInterface</hardwareInterface>
    </joint>
    <actuator name="5">
      <hardwareInterface>hardware_interface/PositionJointInterface</hardwareInterface>
      <mechanicalReduction>1</mechanicalReduction>
    </actuator>
  </transmission>
  <transmission name="r_arm_joint5_trans">
    <provideFeedback>true</provideFeedback>
    <implicitSpringDamper>1</implicitSpringDamper>
    <motorTorqueConstant>0.418</motorTorqueConstant>
    <type>transmission_interface/SimpleTransmission</type>
    <joint name="r_arm_joint5">
      <hardwareInterface>hardware_interface/PositionJointInterface</hardwareInterface>
    </joint>
    <actuator name="6">
      <hardwareInterface>hardware_interface/PositionJointInterface</hardwareInterface>
      <mechanicalReduction>1</mechanicalReduction>
    </actuator>
  </transmission>
  <transmission name="r_arm_joint6_trans">
    <provideFeedback>true</provideFeedback>
    <implicitSpringDamper>1</implicitSpringDamper>
    <motorTorqueConstant>0.418</motorTorqueConstant>
    <type>transmission_interface/SimpleTransmission</type>
    <joint name="r_arm_joint6">
      <hardwareInterface>hardware_interface/PositionJointInterface</hardwareInterface>
    </joint>
    <actuator name="7">
      <hardwareInterface>hardware_interface/PositionJointInterface</hardwareInterface>
      <mechanicalReduction>1</mechanicalReduction>
    </actuator>
  </transmission>
  <transmission name="r_arm_joint7_trans">
    <provideFeedback>true</provideFeedback>
    <implicitSpringDamper>1</implicitSpringDamper>
    <motorTorqueConstant>0.418</motorTorqueConstant>
    <type>transmission_interface/SimpleTransmission</type>
    <joint name="r_arm_joint7">
      <hardwareInterface>hardware_interface/PositionJointInterface</hardwareInterface>
    </joint>
    <actuator name="8">
      <hardwareInterface>hardware_interface/PositionJointInterface</hardwareInterface>
      <mechanicalReduction>1</mechanicalReduction>
    </actuator>
  </transmission>
  <transmission name="r_hand_joint_trans">
    <provideFeedback>true</provideFeedback>
    <implicitSpringDamper>1</implicitSpringDamper>
    <motorTorqueConstant>0.418</motorTorqueConstant>
    <type>transmission_interface/SimpleTransmission</type>
    <joint name="r_hand_joint">
      <hardwareInterface>hardware_interface/PositionJointInterface</hardwareInterface>
    </joint>
    <actuator name="9">
      <hardwareInterface>hardware_interface/PositionJointInterface</hardwareInterface>
      <mechanicalReduction>1</mechanicalReduction>
    </actuator>
  </transmission>

  <transmission name="l_arm_joint1_trans">
    <provideFeedback>true</provideFeedback>
    <implicitSpringDamper>1</implicitSpringDamper>
    <motorTorqueConstant>0.418</motorTorqueConstant>
    <type>transmission_interface/SimpleTransmission</type>
    <joint name="l_arm_joint1">
      <hardwareInterface>hardware_interface/PositionJointInterface</hardwareInterface>
    </joint>
    <actuator name="10">
      <hardwareInterface>hardware_interface/PositionJointInterface</hardwareInterface>
      <mechanicalReduction>1</mechanicalReduction>
    </actuator>
  </transmission>
  <transmission name="l_arm_joint2_trans">
    <provideFeedback>true</provideFeedback>
    <implicitSpringDamper>1</implicitSpringDamper>
    <motorTorqueConstant>0.418</motorTorqueConstant>
    <type>transmission_interface/SimpleTransmission</type>
    <joint name="l_arm_joint2">
      <hardwareInterface>hardware_interface/PositionJointInterface</hardwareInterface>
    </joint>
    <actuator name="11">
      <hardwareInterface>hardware_interface/PositionJointInterface</hardwareInterface>
      <mechanicalReduction>1</mechanicalReduction>
    </actuator>
  </transmission>
  <transmission name="l_arm_joint3_trans">
    <provideFeedback>true</provideFeedback>
    <implicitSpringDamper>1</implicitSpringDamper>
    <motorTorqueConstant>0.418</motorTorqueConstant>
    <type>transmission_interface/SimpleTransmission</type>
    <joint name="l_arm_joint3">
      <hardwareInterface>hardware_interface/PositionJointInterface</hardwareInterface>
    </joint>
    <actuator name="12">
      <hardwareInterface>hardware_interface/PositionJointInterface</hardwareInterface>
      <mechanicalReduction>1</mechanicalReduction>
    </actuator>
  </transmission>
  <transmission name="l_arm_joint4_trans">
    <provideFeedback>true</provideFeedback>
    <implicitSpringDamper>1</implicitSpringDamper>
    <motorTorqueConstant>0.418</motorTorqueConstant>
    <type>transmission_interface/SimpleTransmission</type>
    <joint name="l_arm_joint4">
      <hardwareInterface>hardware_interface/PositionJointInterface</hardwareInterface>
    </joint>
    <actuator name="13">
      <hardwareInterface>hardware_interface/PositionJointInterface</hardwareInterface>
      <mechanicalReduction>1</mechanicalReduction>
    </actuator>
  </transmission>
  <transmission name="l_arm_joint5_trans">
    <provideFeedback>true</provideFeedback>
    <implicitSpringDamper>1</implicitSpringDamper>
    <motorTorqueConstant>0.418</motorTorqueConstant>
    <type>transmission_interface/SimpleTransmission</type>
    <joint name="l_arm_joint5">
      <hardwareInterface>hardware_interface/PositionJointInterface</hardwareInterface>
    </joint>
    <actuator name="14">
      <hardwareInterface>hardware_interface/PositionJointInterface</hardwareInterface>
      <mechanicalReduction>1</mechanicalReduction>
    </actuator>
  </transmission>
  <transmission name="l_arm_joint6_trans">
    <provideFeedback>true</provideFeedback>
    <implicitSpringDamper>1</implicitSpringDamper>
    <motorTorqueConstant>0.418</motorTorqueConstant>
    <type>transmission_interface/SimpleTransmission</type>
    <joint name="l_arm_joint6">
      <hardwareInterface>hardware_interface/PositionJointInterface</hardwareInterface>
    </joint>
    <actuator name="15">
      <hardwareInterface>hardware_interface/PositionJointInterface</hardwareInterface>
      <mechanicalReduction>1</mechanicalReduction>
    </actuator>
  </transmission>
  <transmission name="l_arm_joint7_trans">
    <provideFeedback>true</provideFeedback>
    <implicitSpringDamper>1</implicitSpringDamper>
    <motorTorqueConstant>0.418</motorTorqueConstant>
    <type>transmission_interface/SimpleTransmission</type>
    <joint name="l_arm_joint7">
      <hardwareInterface>hardware_interface/PositionJointInterface</hardwareInterface>
    </joint>
    <actuator name="16">
      <hardwareInterface>hardware_interface/PositionJointInterface</hardwareInterface>
      <mechanicalReduction>1</mechanicalReduction>
    </actuator>
  </transmission>
  <transmission name="l_hand_joint_trans">
    <provideFeedback>true</provideFeedback>
    <implicitSpringDamper>1</implicitSpringDamper>
    <motorTorqueConstant>0.418</motorTorqueConstant>
    <type>transmission_interface/SimpleTransmission</type>
    <joint name="l_hand_joint">
      <hardwareInterface>hardware_interface/PositionJointInterface</hardwareInterface>
    </joint>
    <actuator name="17">
      <hardwareInterface>hardware_interface/PositionJointInterface</hardwareInterface>
      <mechanicalReduction>1</mechanicalReduction>
    </actuator>
  </transmission>

  <gazebo reference="camera_link">
      <sensor type="depth" name="openni_camera_camera">       
          <always_on>1</always_on>
          <visualize>true</visualize>             
          <camera>
              <horizontal_fov>1.047</horizontal_fov>  
              <image>
                  <width>640</width>
                  <height>480</height>
                  <format>R8G8B8</format>
              </image>
              <depth_camera>
              </depth_camera>
              <clip>
                  <near>0.1</near>
                  <far>100</far>
              </clip>
          </camera>
          <plugin name="camera_controller" filename="libgazebo_ros_openni_kinect.so">
              <robotNamespace>sciurus17</robotNamespace>
              <alwaysOn>true</alwaysOn>
                  <updateRate>10.0</updateRate>
                  <cameraName>camera</cameraName>
                  <frameName>openni_camera_link</frameName>                   
              <imageTopicName>rgb/image_raw</imageTopicName>
              <depthImageTopicName>depth/image_raw</depthImageTopicName>
              <pointCloudTopicName>depth/points</pointCloudTopicName>
              <cameraInfoTopicName>rgb/camera_info</cameraInfoTopicName>              
              <depthImageCameraInfoTopicName>depth/camera_info</depthImageCameraInfoTopicName>            
              <pointCloudCutoff>0.4</pointCloudCutoff>                
                  <hackBaseline>0.07</hackBaseline>
                  <distortionK1>0.0</distortionK1>
                  <distortionK2>0.0</distortionK2>
                  <distortionK3>0.0</distortionK3>
                  <distortionT1>0.0</distortionT1>
                  <distortionT2>0.0</distortionT2>
              <CxPrime>0.0</CxPrime>
              <Cx>0.0</Cx>
              <Cy>0.0</Cy>
              <focalLength>0.0</focalLength>
          </plugin>
      </sensor>
  </gazebo>
</robot>
