<?xml version="1.0"?>

<robot xmlns:xacro="http://ros.org/wiki/xacro">

  <xacro:macro name="sciurus17_body"
    params="waist_yaw_upper_limit
            waist_yaw_lower_limit
            waist_yaw_effort_limit
            waist_yaw_velocity_limit
            base_color
            body_color
            camera_color
    ">

    <link name="base_link">
      <visual>
        <geometry>
          <mesh filename="package://sciurus17_description/meshes/visual/Base.stl" scale="1.0 1.0 1.0"/>
        </geometry>
        <material name="${base_color}"/>
      </visual>
      <collision>
        <origin rpy="0 0 0" xyz="0.0 0.0 0.0"/>
        <geometry>
          <mesh filename="package://sciurus17_description/meshes/collision/Base.stl" scale="1.0 1.0 1.0"/>
        </geometry>
      </collision>
      <inertial>
        <origin rpy="0 0 0" xyz="-24.012e-03 0.139e-03 59.566e-03"/>
        <inertia ixx="6398092.663e-09" ixy="-6808.969e-09" ixz="-331509.04e-09" iyy="7611664.357e-09" iyz="2026.354e-09" izz="6331936.461e-09"/>
        <mass value="1722.937e-03"/>
      </inertial>
    </link>

    <joint name="waist_yaw_joint" type="revolute">
      <parent link="base_link" />
      <child link="body_link" />
      <origin xyz="0.0 0.0 0.1315" rpy="0 0 0"/>
      <limit 
        lower="${waist_yaw_upper_limit}" 
        upper="${waist_yaw_lower_limit}" 
        effort="${waist_yaw_effort_limit}" 
        velocity="${waist_yaw_velocity_limit}"/>
      <axis xyz="0 0 1"/>
      <dynamics damping="1.0e-6" friction="0.8"/>
    </joint>

    <link name="body_link">
      <visual>
        <geometry>
          <mesh filename="package://sciurus17_description/meshes/visual/Body.stl" scale="1.0 1.0 1.0"/>
        </geometry>
        <material name="${body_color}"/>
      </visual>
      <collision>
        <origin rpy="0 0 0" xyz="0.0 0.0 0.0"/>
        <geometry>
          <mesh filename="package://sciurus17_description/meshes/collision/Body.stl" scale="1.0 1.0 1.0"/>
        </geometry>
      </collision>
      <inertial>
       <origin rpy="0 0 0" xyz="57.11e-03 0.372e-03 238.229e-03"/>
        <inertia ixx="15601031.58e-09" ixy="-15890.903e-09" ixz="-3805596.494e-09" iyy="13969734.5e-09" iyz="-20695.221e-09" izz="8327993.097e-09"/>
        <mass value="1482.929e-03"/>
      </inertial>
    </link>

    <joint name="chest_camera_joint" type="fixed">
      <parent link="body_link" />
      <child link="chest_camera_link" />
      <origin xyz="0.114576 0.0 0.217659" rpy="-2.7925268032 0 -1.5707963268"/>
    </joint>

    <link name="chest_camera_link">
      <visual>
        <origin xyz="0 0 0" rpy="0 0 0"/>
        <geometry>
          <cylinder length="0.002" radius="0.003"/>
        </geometry>
        <material name="${camera_color}"/>
      </visual>
      <collision>
        <origin xyz="0.0 0.0 0.0" rpy="0 0 0"/>
        <geometry>
          <cylinder length="0.002" radius="0.003"/>
        </geometry>
      </collision>
    </link>

    <gazebo reference="base_link">
      <material>Gazebo/White</material>
    </gazebo>
    <gazebo reference="body_link">
      <material>Gazebo/White</material>
    </gazebo>
    <gazebo reference="chest_camera_link">
      <material>Gazebo/Black</material>
    </gazebo>

  </xacro:macro>

</robot>
